Workbook

Sheet Executive Summary
A1: ASML HOLDING NV - DCF VALUATION ANALYSIS
A2: Professional Valuation Model
A4: KEY ASSUMPTIONS
A5: Assumption | B5: Value
A6: Revenue CAGR (2024-2028) | B6: =Projections!B49 -> 0.093967162
A7: Terminal Growth Rate | B7: ='DCF Calculation'!B20 -> 0.025
A8: WACC | B8: =WACC!C36 -> 0.091742224
A9: Tax Rate | B9: =Projections!B12 -> 0.25
A10: Current Stock Price (EUR) | B10: ='DCF Calculation'!D42 -> 1204
A11: Shares Outstanding (millions) | B11: ='DCF Calculation'!D39 -> 388.15
A13: VALUATION OUTPUT
A14: Metric | B14: Value
A15: Enterprise Value (EUR millions) | B15: ='DCF Calculation'!D29 -> 208306.21
A16: Plus: Cash | B16: ='DCF Calculation'!D34 -> 12916
A17: Less: Debt | B17: ='DCF Calculation'!D35 -> -30955
A18: Equity Value (EUR millions) | B18: ='DCF Calculation'!D36 -> 190267.21
A19: Value per Share (EUR) | B19: ='DCF Calculation'!D40 -> 490.18991
A20: Current Price (EUR) | B20: =B10 -> 1204
A21: Upside/Downside % | B21: ='DCF Calculation'!D43 -> -0.59286552
A23: RECOMMENDATION: | B23: =IF(B21>0.1,"BUY",IF(B21<-0.1,"SELL","HOLD")) -> SELL
A26: VALUATION BRIDGE
A27: PV of FCFs (2024-2033) | B27: ='DCF Calculation'!D16 -> 78702.667
A28: PV of Terminal Value | B28: ='DCF Calculation'!D23 -> 129603.55
A29: Enterprise Value | B29: =B27+B28 -> 208306.21
A30: Plus: Cash | B30: ='DCF Calculation'!D34 -> 12916
A31: Less: Debt | B31: ='DCF Calculation'!D35 -> -30955
A32: Equity Value | B32: =B28+B29-B30 -> 324993.76

Sheet Historical Financials
A1: ASML HISTORICAL FINANCIALS (2019-2023)
A2: All figures in EUR millions
B4: 44561 | C4: 44926 | D4: 31/12/2023 | E4: 45657 | F4: 46022
A5: Income Statement
A6: Net Sales | B6: 18611 | C6: 21173 | D6: 27559 | E6: 28263 | F6: 32667
A7: Cost of sales | B7: 8802 | C7: 10473 | D7: 13423 | E7: 13771 | F7: 15409
A8: Gross profit | B8: 9809 | C8: 10700 | D8: 14136 | E8: 14492 | F8: 17258
A9: Research & Development costs | B9: 2547 | C9: 3254 | D9: 3981 | E9: 4304 | F9: 4699 | H9: R&D as % of revenue | I9: {=B9:F9/B6:F6} -> 0.13685455 | J9: 0.1536863 | K9: 0.14445372 | L9: 0.1522839 | M9: 0.14384547
A10: Selling, General & Administrative costs | B10: 726 | C10: 946 | D10: 1113 | E10: 1166 | F10: 1258 | I10: =AVERAGE(_xlfn.ANCHORARRAY(I9)) -> 0.14622479
A11: EBITDA | B11: 6991 | C11: 7081 | D11: 9699 | E11: 9861 | F11: 12327 | H11: Selling, General & Administrative | I11: {=B10:F10/B6:F6} -> 0.039009188 | J11: 0.044679545 | K11: 0.040386081 | L11: 0.041255352 | M11: 0.038509811
A12: Operating income (EBIT / Income from operations) | B12: 6750 | C12: 6501 | D12: 9042 | E12: 9022 | F12: 11301 | I12: =AVERAGE(_xlfn.ANCHORARRAY(I11)) -> 0.040767995
A13: Net financing income/costs | B13: Not included | C13: Not included | D13: Not included | E13: Not included | F13: Not included
A14: Income tax | B14: Not included | C14: Not included | D14: Not included | E14: Not included | F14: Not included
A15: Net income | B15: 5883 | C15: 5624 | D15: 7839 | E15: 7572 | F15: 9609
A16: Balance Sheet
A17: Total assets | B17: 30231 | C17: 36300 | D17: 39958 | E17: 48590 | F17: 50567
A18: Property, plant & equipment (net) | B18: 2983 | C18: 3944 | D18: 5493 | E18: 6847 | F18: 7894
A19: Cash and cash equivalents | B19: 6952 | C19: 7268 | D19: 7005 | E19: 12736 | F19: 12916
A20: Total liabilities | B20: 20090 | C20: 27489 | D20: 26506 | E20: 30113 | F20: 30955
A21: Total equity | B21: 10141 | C21: 8811 | D21: 13452 | E21: 18477 | F21: 19612
A22: Shares outstanding (basic, weighted average) | B22: 410 | C22: 398 | D22: 394 | E22: 393 | F22: 389
A23: Cash Flow Statement
A24: Net cash from operating activities | B24: 10847 | C24: 8487 | D24: 5443 | E24: 11166 | F24: 12659
A25: Purchase of property, plant & equipment | B25: 940 | C25: 1319 | D25: 2196 | E25: 2083 | F25: 1631
A29: CALCULATED METRICS
A30: Metric
A31: Gross Margin % | B31: =(B8/B6) -> 0.52705389 | C31: =(C8/C6) -> 0.5053606 | D31: =(D8/D6) -> 0.51293588 | E31: =(E8/E6) -> 0.51275519 | F31: =(F8/F6) -> 0.52830073
A32: Operating Margin % | B32: =(B12/B6) -> 0.36268873 | C32: =(C12/C6) -> 0.30704199 | D32: =(D12/D6) -> 0.32809608 | E32: =(E12/E6) -> 0.31921594 | F32: =(F12/F6) -> 0.34594545
A33: Net Margin % | B33: =(B15/B6) -> 0.31610338 | C33: =(C15/C6) -> 0.26562131 | D33: =(D15/D6) -> 0.28444428 | E33: =(E15/E6) -> 0.26791211 | F33: =(F15/F6) -> 0.29415006
A34: Revenue Growth % | C34: =((C6/B6)-1) -> 0.13766052 | D34: =((D6/C6)-1) -> 0.30161054 | E34: =((E6/D6)-1) -> 0.025545194 | F34: =((F6/E6)-1) -> 0.1558221
A35: Cash Flow Statement
A36: Free cash flow (Operating CF – CapEx) | B36: =B24-B25 -> 9907 | C36: =C24-C25 -> 7168 | D36: =D24-D25 -> 3247 | E36: =E24-E25 -> 9083 | F36: =F24-F25 -> 11028
A44: CASH FLOW STATEMENT
A75: Column1 | B75: 31/12/2025 | C75: 31/12/2024 | D75: 31/12/2023 | E75: 31/12/2022 | F75: 31/12/2021
A77: Tax Rate For Calcs | B77: 0.177 | C77: 0.186 | D77: 0.158 | E77: 0.15023
A78: Normalized EBITDA | B78: 12327300000 | C78: 9941200000 | D78: 9976000000 | E78: 7100500000
A79: Total Unusual Items | F79: 213700000
A80: Total Unusual Items Excluding Goodwill | F80: 213700000
A81: Net Income From Continuing Operation Net Minority Interest | B81: 9609400000 | C81: 7571600000 | D81: 7839000000 | E81: 5624200000
A82: Reconciled Depreciation | B82: 1025900000 | C82: 918600000 | D82: 739800000 | E82: 583600000
...

Sheet DCF Calculation
A1: DISCOUNTED CASH FLOW (DCF) VALUATION
A2: Present value of projected free cash flows
C3: WACC: | D3: =WACC!C36 -> 0.091742224
A4: Year | B4: Free Cash Flow | C4: Discount Factor | D4: Present Value of FCF | E4: Notes
A5: 2026 | B5: =Projections!B43 -> 2902.2579 | C5: =1/(1+$D$3)^(A5-2025) -> 0.91596714 | D5: =B5*C5 -> 2658.3729 | E5: Year 1 FCF discounted to present
A6: =A5+1 -> 2027 | B6: =Projections!C$43 -> 8972.6541 | C6: =1/(1+$D$3)^(A6-2025) -> 0.8389958 | D6: =B6*C6 -> 7528.0191
A7: =A6+1 -> 2028 | B7: =Projections!D$43 -> 10318.552 | C7: =1/(1+$D$3)^(A7-2025) -> 0.76849258 | D7: =B7*C7 -> 7929.7308
A8: =A7+1 -> 2029 | B8: =Projections!E$43 -> 11866.335 | C8: =1/(1+$D$3)^(A8-2025) -> 0.70391395 | D8: =B8*C8 -> 8352.8788
A9: =A8+1 -> 2030 | B9: =Projections!F$43 -> 13425.587 | C9: =1/(1+$D$3)^(A9-2025) -> 0.64476204 | D9: =B9*C9 -> 8656.3088
A10: =A9+1 -> 2031 | B10: =Projections!G$43 -> 14768.145 | C10: =1/(1+$D$3)^(A10-2025) -> 0.59058084 | D10: =B10*C10 -> 8721.7838
A11: =A10+1 -> 2032 | B11: =Projections!H$43 -> 16244.96 | C11: =1/(1+$D$3)^(A11-2025) -> 0.54095265 | D11: =B11*C11 -> 8787.7541
A12: =A11+1 -> 2033 | B12: =Projections!I$43 -> 17869.456 | C12: =1/(1+$D$3)^(A12-2025) -> 0.49549485 | D12: =B12*C12 -> 8854.2234
A13: =A12+1 -> 2034 | B13: =Projections!J$43 -> 19333.277 | C13: =1/(1+$D$3)^(A13-2025) -> 0.453857 | D13: =B13*C13 -> 8774.543
A14: =A13+1 -> 2035 | B14: =Projections!K$43 -> 20299.941 | C14: =1/(1+$D$3)^(A14-2025) -> 0.41571809 | D14: =B14*C14 -> 8439.0526 | E14: Year 10 FCF discounted to present
A16: Total PV of Projected FCFs (2024-2033) | D16: =SUM(D5:D14) -> 78702.667
A19: TERMINAL VALUE CALCULATION
A20: Terminal Growth Rate: | B20: 0.025
A21: Terminal Year FCF (2036): | D21: =B14*(1+B20) -> 20807.439 | E21: Year 11 FCF (first year of perpetuity)
A22: Terminal Value (2035): | D22: =D21/(D3-B20) -> 311758.25 | E22: TV = FCF / (WACC - g) - perpetuity formula
A23: PV of Terminal Value: | D23: =D22*C14 -> 129603.55 | E23: TV discounted to Year 0 (today)
A26: ENTERPRISE VALUE
A27: Sum of PV of FCFs (2024-2033): | D27: =D16 -> 78702.667
A28: Plus: PV of Terminal Value: | D28: =D23 -> 129603.55
A29: Enterprise Value: | D29: =D27+D28 -> 208306.21 | E29: Sum of all discounted cash flows
A31: EQUITY VALUE CALCULATION
A32: Enterprise Value: | D32: =D29 -> 208306.21
A34: Plus: Cash & Cash Equivalents: | D34: ='Historical Financials'!F19 -> 12916
A35: Less: Total Debt: | D35: =-'Historical Financials'!F20 -> -30955
A36: Equity Value: | D36: =D32+D34+D35 -> 190267.21 | E36: Value of equity (after debt/cash adj.)
A39: Shares Outstanding (millions): | D39: 388.15 | E39: Intrinsic value per share based on DCF
A40: DCF VALUE PER SHARE (EUR): | D40: =D36/D39 -> 490.18991
A42: Current Market Price (EUR): | D42: 1204
A43: Implied Upside/(Downside): | D43: =(D40-D42)/D42 -> -0.59286552

Sheet Projections
A1: ASML FINANCIAL PROJECTIONS (2024-2033)
A2: 10-Year Forecast - All figures in EUR millions
A3: Line Item | B3: 2026E | C3: 2027E | D3: 2028E | E3: 2029E | F3: 2030E | G3: 2031E | H3: 2032E | I3: 2033E | J3: 2034E | K3: 2035E
A6: GROWTH ASSUMPTIONS
A7: Revenue Growth Rate % | B7: 0.15 | C7: 0.15 | D7: 0.15 | E7: 0.15 | F7: 0.1 | G7: 0.1 | H7: 0.1 | I7: 0.1 | J7: 0.05 | K7: 0.05
A9: MARGIN ASSUMPTIONS
A10: Gross Margin % | B10: 0.57 | C10: 0.57 | D10: 0.57 | E10: 0.57 | F10: 0.57 | G10: 0.57 | H10: 0.57 | I10: 0.57 | J10: 0.57 | K10: 0.57
A11: EBIT Margin % | B11: 0.375 | C11: 0.375 | D11: 0.375 | E11: 0.375 | F11: 0.375 | G11: 0.375 | H11: 0.375 | I11: 0.375 | J11: 0.375 | K11: 0.375
A12: Tax Rate % | B12: 0.25 | C12: 0.25 | D12: 0.25 | E12: 0.25 | F12: 0.25 | G12: 0.25 | H12: 0.25 | I12: 0.25 | J12: 0.25 | K12: 0.25
A14: CAPEX & WORKING CAPITAL ASSUMPTIONS
A15: CapEx % of Revenue | B15: 0.09 | C15: 0.09 | D15: 0.09 | E15: 0.09 | F15: 0.09 | G15: 0.09 | H15: 0.09 | I15: 0.09 | J15: 0.09 | K15: 0.09
A16: D&A % of Prior PP&E | B16: 0.1 | C16: 0.1 | D16: 0.1 | E16: 0.1 | F16: 0.1 | G16: 0.1 | H16: 0.1 | I16: 0.1 | J16: 0.1 | K16: 0.1
A17: NWC % of Revenue | B17: 0.15 | C17: 0.15 | D17: 0.15 | E17: 0.15 | F17: 0.15 | G17: 0.15 | H17: 0.15 | I17: 0.15 | J17: 0.15 | K17: 0.15
A20: INCOME STATEMENT PROJECTIONS
A21: Revenue | B21: ='Historical Financials'!F6*(1+B7) -> 37567.05 | C21: =B21*(1+C7) -> 43202.107 | D21: =C21*(1+D7) -> 49682.424 | E21: =D21*(1+E7) -> 57134.787 | F21: =E21*(1+F7) -> 62848.266 | G21: =F21*(1+G7) -> 69133.092 | H21: =G21*(1+H7) -> 76046.402 | I21: =H21*(1+I7) -> 83651.042 | J21: =I21*(1+J7) -> 87833.594 | K21: =J21*(1+K7) -> 92225.274
A22: Cost of Goods Sold (COGS) | B22: =B21*(1-B10) -> 16153.832 | C22: =C21*(1-C10) -> 18576.906 | D22: =D21*(1-D10) -> 21363.442 | E22: =E21*(1-E10) -> 24567.958 | F22: =F21*(1-F10) -> 27024.754 | G22: =G21*(1-G10) -> 29727.23 | H22: =H21*(1-H10) -> 32699.953 | I22: =I21*(1-I10) -> 35969.948 | ... K22: =K21*(1-K10) -> 39656.868
A23: Gross Profit | B23: =B21-B22 -> 21413.218 | C23: =C21-C22 -> 24625.201 | D23: =D21-D22 -> 28318.981 | E23: =E21-E22 -> 32566.829 | F23: =F21-F22 -> 35823.512 | G23: =G21-G22 -> 39405.863 | H23: =H21-H22 -> 43346.449 | I23: =I21-I22 -> 47681.094 | ... K23: =K21-K22 -> 52568.406
A25: Research & Development | B25: =B21*'Historical Financials'!$I$10 -> 5493.2339 | C25: =C21*'Historical Financials'!$I$10 -> 6317.219 | D25: =D21*'Historical Financials'!$I$10 -> 7264.8019 | E25: =E21*'Historical Financials'!$I$10 -> 8354.5221 | F25: =F21*'Historical Financials'!$I$10 -> 9189.9744 | G25: =G21*'Historical Financials'!$I$10 -> 10108.972 | H25: =H21*'Historical Financials'!$I$10 -> 11119.869 | I25: =I21*'Historical Financials'!$I$10 -> 12231.856 | ... K25: =K21*'Historical Financials'!$I$10 -> 13485.621
A26: Selling, General & Administrative | B26: =B21*'Historical Financials'!$I$12 -> 1531.5333 | C26: =C21*'Historical Financials'!$I$12 -> 1761.2633 | D26: =D21*'Historical Financials'!$I$12 -> 2025.4528 | E26: =E21*'Historical Financials'!$I$12 -> 2329.2707 | F26: =F21*'Historical Financials'!$I$12 -> 2562.1978 | G26: =G21*'Historical Financials'!$I$12 -> 2818.4176 | H26: =H21*'Historical Financials'!$I$12 -> 3100.2593 | I26: =I21*'Historical Financials'!$I$12 -> 3410.2853 | ... K26: =K21*'Historical Financials'!$I$12 -> 3759.8395
A28: Total Operating Expenses | B28: =B25+B26 -> 7024.7672 | C28: =C25+C26 -> 8078.4823 | D28: =D25+D26 -> 9290.2547 | E28: =E25+E26 -> 10683.793 | F28: =F25+F26 -> 11752.172 | G28: =G25+G26 -> 12927.389 | H28: =H25+H26 -> 14220.128 | I28: =I25+I26 -> 15642.141 | ... K28: =K25+K26 -> 17245.461
A30: Operating Income (EBIT) | B30: =B23-B28 -> 14388.451 | C30: =C23-C28 -> 16546.719 | D30: =D23-D28 -> 19028.727 | E30: =E23-E28 -> 21883.036 | F30: =F23-F28 -> 24071.339 | G30: =G23-G28 -> 26478.473 | H30: =H23-H28 -> 29126.321 | I30: =I23-I28 -> 32038.953 | ... K30: =K23-K28 -> 35322.945
A32: Income Tax Expense | B32: =B30*B12 -> 3597.1128 | C32: =C30*C12 -> 4136.6797 | D32: =D30*D12 -> 4757.1817 | E32: =E30*E12 -> 5470.759 | F32: =F30*F12 -> 6017.8348 | G32: =G30*G12 -> 6619.6183 | H32: =H30*H12 -> 7281.5802 | I32: =I30*I12 -> 8009.7382 | ... K32: =K30*K12 -> 8830.7363
A34: Net Operating Profit After Tax (NOPAT) | B34: =B30-B32 -> 10791.338 | C34: =C30-C32 -> 12410.039 | D34: =D30-D32 -> 14271.545 | E34: =E30-E32 -> 16412.277 | F34: =F30-F32 -> 18053.505 | G34: =G30-G32 -> 19858.855 | H34: =H30-H32 -> 21844.74 | I34: =I30-I32 -> 24029.215 | ... K34: =K30-K32 -> 26492.209
A37: FREE CASH FLOW CALCULATION
A38: Depreciation & Amortization (D&A) | B38: =B21*0.03 -> 1127.0115 | C38: =C21*0.03 -> 1296.0632 | D38: =D21*0.03 -> 1490.4727 | E38: =E21*0.03 -> 1714.0436 | F38: =F21*0.03 -> 1885.448 | G38: =G21*0.03 -> 2073.9928 | H38: =H21*0.03 -> 2281.3921 | I38: =I21*0.03 -> 2509.5313 | ... K38: =K21*0.03 -> 2766.7582
A39: Capital Expenditures (CapEx) | B39: =B21*B15 -> 3381.0345 | C39: =C21*C15 -> 3888.1897 | D39: =D21*D15 -> 4471.4181 | E39: =E21*E15 -> 5142.1308 | F39: =F21*F15 -> 5656.3439 | G39: =G21*G15 -> 6221.9783 | H39: =H21*H15 -> 6844.1762 | I39: =I21*I15 -> 7528.5938 | ... K39: =K21*K15 -> 8300.2746
A40: Net Working Capital (NWC) | B40: =B21*B17 -> 5635.0575 | C40: =C21*C17 -> 6480.3161 | D40: =D21*D17 -> 7452.3635 | E40: =E21*E17 -> 8570.2181 | F40: =F21*F17 -> 9427.2399 | G40: =G21*G17 -> 10369.964 | H40: =H21*H17 -> 11406.96 | I40: =I21*I17 -> 12547.656 | ... K40: =K21*K17 -> 13833.791
A41: Change in Net Working Capital | B41: =B40 -> 5635.0575 | C41: =C40-B40 -> 845.25862 | D41: =D40-C40 -> 972.04742 | E41: =E40-D40 -> 1117.8545 | F41: =F40-E40 -> 857.02181 | G41: =G40-F40 -> 942.72399 | H41: =H40-G40 -> 1036.9964 | I41: =I40-H40 -> 1140.696 | J41: =J40-I40 -> 627.38281 | K41: =K40-J40 -> 658.75195
A43: Unlevered Free Cash Flow (FCF) | B43: =B34+B38-B39-B41 -> 2902.2579 | C43: =C34+C38-C39-C41 -> 8972.6541 | D43: =D34+D38-D39-D41 -> 10318.552 | E43: =E34+E38-E39-E41 -> 11866.335 | F43: =F34+F38-F39-F41 -> 13425.587 | G43: =G34+G38-G39-G41 -> 14768.145 | H43: =H34+H38-H39-H41 -> 16244.96 | I43: =I34+I38-I39-I41 -> 17869.456 | ... K43: =K34+K38-K39-K41 -> 20299.941
A46: SUMMARY METRICS
A47: Average Annual FCF (Years 1-10) | B47: =AVERAGE(B43:K43) -> 13600.117
A48: Total FCF (Years 1-10) | B48: =SUM(B43:K43) -> 136001.17
A49: Revenue CAGR (2024-2033) | B49: =((K21/B21)^(1/10))-1 -> 0.093967162

Sheet WACC
A1: WEIGHTED AVERAGE COST OF CAPITAL (WACC)
A2: CAPM-based calculation
A5: COST OF EQUITY (Re) - CAPM METHOD
A7: Risk-Free Rate (Rf): | B7: 10-Year US Treasury Yield | C7: 0.00425
A8: Beta (β): | B8: Calculated from 2-year monthly returns | C8: 1.35
A9: Market Risk Premium (Rm - Rf): | B9: Historical equity premium | C9: 0.065
A11: Cost of Equity (Re): | B11: Re = Rf + β × (Rm - Rf) | C11: =C7+C8*C9 -> 0.092
A14: COST OF DEBT (Rd)
A16: Interest Expense (2025): | B16: From Historical Financials (from Q4 2025 US GAAP financial statements) | C16: 141
A17: Total Debt (2025): | B17: Short-term + Long-term (from Q4 2025 US GAAP financial statements) | C17: 2709
A19: Pre-Tax Cost of Debt (Rd): | B19: Interest Expense / Total Debt | C19: =C16/C17 -> 0.052048726
A20: Tax Rate: | B20: Netherlands corporate tax | C20: 0.25
A22: After-Tax Cost of Debt (Rd×(1-T)): | B22: Rd × (1 - Tax Rate) | C22: =C19*(1-C20) -> 0.039036545
A25: CAPITAL STRUCTURE
A27: Market Value of Equity (E): | B27: Current Price × Shares Outstanding | C27: ='DCF Calculation'!D42*'DCF Calculation'!D39 -> 467332.6
A28: Market Value of Debt (D): | B28: Book value used as proxy | C28: =C17 -> 2709
A30: Total Value (V = E + D): | C30: =C27+C28 -> 470041.6
A32: Weight of Equity (E/V): | C32: =C27/C30 -> 0.99423668
A33: Weight of Debt (D/V): | C33: =C28/C30 -> 0.0057633197
A36: WEIGHTED AVERAGE COST OF CAPITAL (WACC): | B36: WACC = (E/V × Re) + (D/V × Rd × (1-T)) | C36: 0.091742224

Sheet Comparables
A1: COMPARABLE COMPANY ANALYSIS
A2: Semiconductor Equipment Manufacturers
A4: Company | B4: Market Cap ($B) | C4: EV/EBITDA | D4: P/E Ratio | E4: EV/Revenue | F4: Gross Margin | G4: Beta | H4: Revenue Growth
A5: ASML | B5: 545.7 | C5: =WACC!C30/'Historical Financials'!F11 -> 38.131062 | D5: 48.46 | E5: 13.86 | F5: 0.57 | G5: 1.35 | H5: 0.049
A6: Applied Materials | B6: 255.98 | C6: 25.51 | D6: 37.24 | E6: 8.97 | F6: 0.4867 | G6: 1.68 | H6: -0.035
A7: LAM Research | B7: 288.48 | C7: 37.81 | D7: 47.44 | E7: 13.95 | F7: 0.498 | G7: 1.78 | H7: 0.221
A8: KLA Corp | B8: 189.14 | C8: 32.16 | D8: 42.01 | E8: 14.91 | F8: 0.6157 | G8: 1.46 | H8: 0.072
A11: Peer Median (ex-ASML) | B11: =MEDIAN(B6:B9) -> 255.98 | C11: =MEDIAN(C6:C9) -> 32.16 | D11: =MEDIAN(D6:D9) -> 42.01 | E11: =MEDIAN(E6:E9) -> 13.95 | F11: =MEDIAN(F6:F9) -> 0.498 | G11: =MEDIAN(G6:G9) -> 1.68 | H11: =MEDIAN(H6:H9) -> 0.072
A12: Peer Average (ex-ASML) | B12: =AVERAGE(B6:B9) -> 244.53333 | C12: =AVERAGE(C6:C9) -> 31.826667 | D12: =AVERAGE(D6:D9) -> 42.23 | E12: =AVERAGE(E6:E9) -> 12.61 | F12: =AVERAGE(F6:F9) -> 0.53346667 | G12: =AVERAGE(G6:G9) -> 1.64 | H12: =AVERAGE(H6:H9) -> 0.086
A14: ASML Premium/(Discount) to Median | B14: =(B5/B11)-1 -> 1.1318072 | C14: =(C5/C11)-1 -> 0.18566735 | D14: =(D5/D11)-1 -> 0.15353487 | E14: =(E5/E11)-1 -> -0.0064516129 | F14: =(F5/F11)-1 -> 0.14457831 | G14: =(G5/G11)-1 -> -0.19642857 | H14: =(H5/H11)-1 -> -0.31944444
A17: IMPLIED VALUATION AT PEER MULTIPLES
A18: ASML EBITDA (EUR millions): | C18: ='Historical Financials'!F11 -> 12327
A19: EV at Sector Median EV/EBITDA (17.9x): | C19: =C18*C11 -> 396436.32
A20: Implied Equity Value: | C20: =C19+'Historical Financials'!F19-'Historical Financials'!F20 -> 378397.32
A21: Implied Price Per Share (EUR): | C21: =C20/'DCF Calculation'!D39 -> 974.87394
A23: ASML Current Price: | C23: ='DCF Calculation'!D42 -> 1204
A24: Implied by Peer Multiples: | C24: =C21 -> 974.87394
A25: Premium/(Discount): | C25: =(C24-C23)/C23 -> -0.19030404

Sheet Sensitivity
A1: SENSITIVITY ANALYSIS
A2: DCF Value Per Share under different WACC and Terminal Growth scenarios
B4: WACC
A5: Terminal Growth | B5: 0.08 | C5: 0.085 | D5: 0.09 | E5: 0.095 | F5: 0.1 | G5: 0.105 | H5: 0.11 | I5: 0.115 | J5: 0.12 | K5: 0.125 | L5: 0.13
A6: 0.015 | B6: 548.07044 | C6: 499.29924 | D6: 457.19366 | E6: 420.49826 | F6: 388.25326 | G6: 359.71235 | H6: 334.28653 | I6: 311.50476 | J6: 290.9859 | K6: 272.41822 | L6: 255.54434 | O6: WACC | P6: =WACC!C36 -> 0.091742224
A7: 0.02 | B7: 581.61227 | C7: 526.87872 | D7: 480.127 | E7: 439.75518 | F7: 404.56207 | G7: 373.62927 | H7: 346.2427 | I7: 321.83874 | J7: 299.96667 | K7: 280.26173 | L7: 262.42561 | O7: Terminal Growth | P7: ='DCF Calculation'!B20 -> 0.025
A8: 0.025 | B8: 621.25262 | C8: 559.05479 | D8: 506.58855 | E8: 461.76309 | F8: 423.04538 | G8: 389.28581 | H8: 359.60548 | I8: 333.32095 | J8: 309.89279 | K8: 288.88959 | L8: 269.96224 | O8: DCF value per share (EUR): | P8: 490.18991
A9: 0.03 | B9: 668.82103 | C9: 597.08105 | D9: 537.46036 | E9: 487.15684 | F9: 444.16916 | G9: 407.02989 | H9: 374.63862 | I9: 346.154 | J9: 320.9218 | K9: 298.42565 | L9: 278.25254
A10: 0.035 | B10: 726.96021 | C10: 642.71256 | D10: 573.94523 | E10: 516.78287 | F10: 468.54276 | G10: 427.30884 | H10: 391.67617 | I10: 360.59118 | J10: 333.24835 | K10: 309.02127 | L10: 287.41549
A11: 0.04 | B11: 799.63418 | C11: 698.4844 | D11: 617.72707 | E11: 551.79545 | F11: 496.97862 | G11: 450.70762 | H11: 411.14765 | I11: 376.95332 | J11: 347.11572 | K11: 320.86343 | L11: 297.59655
A12: 0.045 | B12: 893.07214 | C12: 768.19921 | D12: 671.23821 | E12: 593.81056 | F12: 530.58464 | G12: 478.0062 | H12: 433.61475 | I12: 395.65291 | J12: 362.83207 | K12: 334.18586 | L12: 308.97539
A13: 0.05 | B13: 1017.6561 | C13: 857.83254 | D13: 738.12713 | E13: 645.16235 | F13: 570.91186 | G13: 510.26816 | H13: 459.82636 | I13: 417.22936 | J13: 380.79362 | K13: 349.28462 | L13: 321.77658
A15: Current Market Price: €1204
A16: Green = Undervalued | Red = Overvalued
A19: KEY INSIGHTS FROM SENSITIVITY ANALYSIS
A20: Valuation ranges from €256 (most conservative) to €1018 (most aggressive)
A21: Base case (9.5% WACC, 2.5% growth) yields €462 per share
A22: WACC is the more sensitive driver
A23: Terminal growth less sensitive

Sheet Data & Sources
A1: DATA SOURCES & ASSUMPTIONS LOG
A3: Item | B3: Value | C3: Source
A4: 2025 Revenue | B4: €32,667M | C4: ASML Annual Report 2025 via yfinance
A5: Revenue Growth (2026-2030) | B5: 15% CAGR | C5: Management guidance + Industry analysis
A6: Revenue Growth (2030-2032) | B6: 10% CAGR | C6: Industry maturation assumption
A7: Revenue Growth (2032-2035) | B7: 5% CAGR | C7: Mature growth assumption
A8: Gross Margin | B8: 0.57 | C8: 5-year historical average
A9: EBIT Margin | B9: 0.375 | C9: Historical average with slight expansion
A10: Tax Rate | B10: 0.25 | C10: Netherlands corporate tax rate
A11: CapEx % of Revenue | B11: 0.09 | C11: 5-year historical average
A12: NWC % of Revenue | B12: 0.15 | C12: Historical working capital intensity
A13: D&A % of Revenue | B13: 0.03 | C13: Historical depreciation rate
A14: Risk-Free Rate | B14: 0.0425 | C14: 10-Year US Treasury as of February 2026
A15: Beta | B15: 1.35 | C15: Calculated from 24-month returns vs S&P 500
A16: Market Risk Premium | B16: 0.065 | C16: Historical equity premium (Damodaran)
A17: Cost of Equity | B17: 0.133 | C17: CAPM calculation
A18: Cost of Debt | B18: 0.025 | C18: Interest expense / Total debt
A19: WACC | B19: =WACC!C36 -> 0.091742224 | C19: Weighted average calculation
A20: Terminal Growth | B20: 0.025 | C20: Long-term GDP growth assumption
A21: Current Stock Price | B21: 1204 | C21: Yahoo Finance as of February 2026
A22: Shares Outstanding | B22: 338M | C22: Company filings
A25: PRIMARY DATA SOURCES
A26: Source | B26: Description
A27: Yahoo Finance | B27: Historical financials
A28: ASML Investor Relations | B28: Annual reports, presentations
A29: Federal Reserve | B29: Risk-free rate (10Y Treasury)
A30: Damodaran Data | B30: Market risk premium
A31: FactSet / Bloomberg | B31: Comparable company data
A33: Model Info
A34: Item | B34: Value
A35: Model Created | B35: 46267
A36: Model Version | B36: 3
A37: Created By | B37: Stanley Vanderzypen
A38: Last Updated | B38: 46267
A39: Purpose | B39: Internship applications
